Workbook

Sheet Inputs
B2: Trade ID | C2: Trade Date | D2: Maturity | E2: Coupon | F2: Frequency | G2: Months | I2: Notional | J2: 10000000
B3: T001 | C3: 46097 | D3: 52963 | E3: 0.0725 | F3: Quarterly | G3: =IF(F3 = "Annual",12, IF(F3 = "Semi",6, IF(F3 = "Quarterly", 3, ""))) -> 3 | I3: Day Count | J3: ACT/365F
I4: Business Day Convention | J4: Following

Sheet Raw Schedule
B2: Coupon No. | C2: Coupon Date | D2: Keep?
B3: 0 | C3: =Inputs!D3 -> 52963 | D3: =IF(C3>Inputs!$C$3, "Keep", "Discard") -> Keep
B4: 1 | C4: =EDATE(C3,-Inputs!$G$3) -> 52871 | D4: =IF(C4>Inputs!$C$3, "Keep", "Discard") -> Keep
B5: 2 | C5: =EDATE(C4,-Inputs!$G$3) -> 52779 | D5: =IF(C5>Inputs!$C$3, "Keep", "Discard") -> Keep
B6: =B5+1 -> 3 | C6: =EDATE(C5,-Inputs!$G$3) -> 52688 | D6: =IF(C6>Inputs!$C$3, "Keep", "Discard") -> Keep
B7: =B6+1 -> 4 | C7: =EDATE(C6,-Inputs!$G$3) -> 52597 | D7: =IF(C7>Inputs!$C$3, "Keep", "Discard") -> Keep
B8: =B7+1 -> 5 | C8: =EDATE(C7,-Inputs!$G$3) -> 52505 | D8: =IF(C8>Inputs!$C$3, "Keep", "Discard") -> Keep
B9: =B8+1 -> 6 | C9: =EDATE(C8,-Inputs!$G$3) -> 52413 | D9: =IF(C9>Inputs!$C$3, "Keep", "Discard") -> Keep
B10: =B9+1 -> 7 | C10: =EDATE(C9,-Inputs!$G$3) -> 52322 | D10: =IF(C10>Inputs!$C$3, "Keep", "Discard") -> Keep
B11: =B10+1 -> 8 | C11: =EDATE(C10,-Inputs!$G$3) -> 52232 | D11: =IF(C11>Inputs!$C$3, "Keep", "Discard") -> Keep
B12: =B11+1 -> 9 | C12: =EDATE(C11,-Inputs!$G$3) -> 52140 | D12: =IF(C12>Inputs!$C$3, "Keep", "Discard") -> Keep
B13: =B12+1 -> 10 | C13: =EDATE(C12,-Inputs!$G$3) -> 52048 | D13: =IF(C13>Inputs!$C$3, "Keep", "Discard") -> Keep
B14: =B13+1 -> 11 | C14: =EDATE(C13,-Inputs!$G$3) -> 51957 | D14: =IF(C14>Inputs!$C$3, "Keep", "Discard") -> Keep
B15: =B14+1 -> 12 | C15: =EDATE(C14,-Inputs!$G$3) -> 51867 | D15: =IF(C15>Inputs!$C$3, "Keep", "Discard") -> Keep
B16: =B15+1 -> 13 | C16: =EDATE(C15,-Inputs!$G$3) -> 51775 | D16: =IF(C16>Inputs!$C$3, "Keep", "Discard") -> Keep
B17: =B16+1 -> 14 | C17: =EDATE(C16,-Inputs!$G$3) -> 51683 | D17: =IF(C17>Inputs!$C$3, "Keep", "Discard") -> Keep
... B113: =B112+1 -> 110 | C113: =EDATE(C112,-Inputs!$G$3) -> 42917 | D113: =IF(C113>Inputs!$C$3, "Keep", "Discard") -> Discard

Sheet Final Schedule
B2: Coupon Number | C2: Coupon Date | D2: Final Payment
B3: {=SEQUENCE(COUNTA(C3:C100),1)} -> 1 | C3: =IFERROR(__xludf.DUMMYFUNCTION("SORT(FILTER('Raw Schedule'!C3:C100,'Raw Schedule'!D3:D100 = ""Keep""))"),46113.0) -> 46113 | D3: =IF(C3 = MAX($C$3:$C$100), "Yes", "No") -> No
B4: 2 | C4: =IFERROR(__xludf.DUMMYFUNCTION("""COMPUTED_VALUE"""),46204.0) -> 46204 | D4: =IF(C4 = MAX($C$3:$C$100), "Yes", "No") -> No
B5: 3 | C5: =IFERROR(__xludf.DUMMYFUNCTION("""COMPUTED_VALUE"""),46296.0) -> 46296 | D5: =IF(C5 = MAX($C$3:$C$100), "Yes", "No") -> No
B6: 4 | C6: =IFERROR(__xludf.DUMMYFUNCTION("""COMPUTED_VALUE"""),46388.0) -> 46388 | D6: =IF(C6 = MAX($C$3:$C$100), "Yes", "No") -> No
B7: 5 | C7: =IFERROR(__xludf.DUMMYFUNCTION("""COMPUTED_VALUE"""),46478.0) -> 46478 | D7: =IF(C7 = MAX($C$3:$C$100), "Yes", "No") -> No
B8: 6 | C8: =IFERROR(__xludf.DUMMYFUNCTION("""COMPUTED_VALUE"""),46569.0) -> 46569 | D8: =IF(C8 = MAX($C$3:$C$100), "Yes", "No") -> No
B9: 7 | C9: =IFERROR(__xludf.DUMMYFUNCTION("""COMPUTED_VALUE"""),46661.0) -> 46661 | D9: =IF(C9 = MAX($C$3:$C$100), "Yes", "No") -> No
B10: 8 | C10: =IFERROR(__xludf.DUMMYFUNCTION("""COMPUTED_VALUE"""),46753.0) -> 46753 | D10: =IF(C10 = MAX($C$3:$C$100), "Yes", "No") -> No
B11: 9 | C11: =IFERROR(__xludf.DUMMYFUNCTION("""COMPUTED_VALUE"""),46844.0) -> 46844 | D11: =IF(C11 = MAX($C$3:$C$100), "Yes", "No") -> No
B12: 10 | C12: =IFERROR(__xludf.DUMMYFUNCTION("""COMPUTED_VALUE"""),46935.0) -> 46935 | D12: =IF(C12 = MAX($C$3:$C$100), "Yes", "No") -> No
B13: 11 | C13: =IFERROR(__xludf.DUMMYFUNCTION("""COMPUTED_VALUE"""),47027.0) -> 47027 | D13: =IF(C13 = MAX($C$3:$C$100), "Yes", "No") -> No
B14: 12 | C14: =IFERROR(__xludf.DUMMYFUNCTION("""COMPUTED_VALUE"""),47119.0) -> 47119 | D14: =IF(C14 = MAX($C$3:$C$100), "Yes", "No") -> No
B15: 13 | C15: =IFERROR(__xludf.DUMMYFUNCTION("""COMPUTED_VALUE"""),47209.0) -> 47209 | D15: =IF(C15 = MAX($C$3:$C$100), "Yes", "No") -> No
B16: 14 | C16: =IFERROR(__xludf.DUMMYFUNCTION("""COMPUTED_VALUE"""),47300.0) -> 47300 | D16: =IF(C16 = MAX($C$3:$C$100), "Yes", "No") -> No
B17: 15 | C17: =IFERROR(__xludf.DUMMYFUNCTION("""COMPUTED_VALUE"""),47392.0) -> 47392 | D17: =IF(C17 = MAX($C$3:$C$100), "Yes", "No") -> No
B18: 16 | C18: =IFERROR(__xludf.DUMMYFUNCTION("""COMPUTED_VALUE"""),47484.0) -> 47484 | D18: =IF(C18 = MAX($C$3:$C$100), "Yes", "No") -> No
B19: 17 | C19: =IFERROR(__xludf.DUMMYFUNCTION("""COMPUTED_VALUE"""),47574.0) -> 47574 | D19: =IF(C19 = MAX($C$3:$C$100), "Yes", "No") -> No
B20: 18 | C20: =IFERROR(__xludf.DUMMYFUNCTION("""COMPUTED_VALUE"""),47665.0) -> 47665 | D20: =IF(C20 = MAX($C$3:$C$100), "Yes", "No") -> No
B21: 19 | C21: =IFERROR(__xludf.DUMMYFUNCTION("""COMPUTED_VALUE"""),47757.0) -> 47757 | D21: =IF(C21 = MAX($C$3:$C$100), "Yes", "No") -> No
B22: 20 | C22: =IFERROR(__xludf.DUMMYFUNCTION("""COMPUTED_VALUE"""),47849.0) -> 47849 | D22: =IF(C22 = MAX($C$3:$C$100), "Yes", "No") -> No
B23: 21 | C23: =IFERROR(__xludf.DUMMYFUNCTION("""COMPUTED_VALUE"""),47939.0) -> 47939 | D23: =IF(C23 = MAX($C$3:$C$100), "Yes", "No") -> No
B24: 22 | C24: =IFERROR(__xludf.DUMMYFUNCTION("""COMPUTED_VALUE"""),48030.0) -> 48030 | D24: =IF(C24 = MAX($C$3:$C$100), "Yes", "No") -> No
B25: 23 | C25: =IFERROR(__xludf.DUMMYFUNCTION("""COMPUTED_VALUE"""),48122.0) -> 48122 | D25: =IF(C25 = MAX($C$3:$C$100), "Yes", "No") -> No
B26: 24 | C26: =IFERROR(__xludf.DUMMYFUNCTION("""COMPUTED_VALUE"""),48214.0) -> 48214 | D26: =IF(C26 = MAX($C$3:$C$100), "Yes", "No") -> No
B27: 25 | C27: =IFERROR(__xludf.DUMMYFUNCTION("""COMPUTED_VALUE"""),48305.0) -> 48305 | D27: =IF(C27 = MAX($C$3:$C$100), "Yes", "No") -> No
B28: 26 | C28: =IFERROR(__xludf.DUMMYFUNCTION("""COMPUTED_VALUE"""),48396.0) -> 48396 | D28: =IF(C28 = MAX($C$3:$C$100), "Yes", "No") -> No
B29: 27 | C29: =IFERROR(__xludf.DUMMYFUNCTION("""COMPUTED_VALUE"""),48488.0) -> 48488 | D29: =IF(C29 = MAX($C$3:$C$100), "Yes", "No") -> No
B30: 28 | C30: =IFERROR(__xludf.DUMMYFUNCTION("""COMPUTED_VALUE"""),48580.0) -> 48580 | D30: =IF(C30 = MAX($C$3:$C$100), "Yes", "No") -> No
B31: 29 | C31: =IFERROR(__xludf.DUMMYFUNCTION("""COMPUTED_VALUE"""),48670.0) -> 48670 | D31: =IF(C31 = MAX($C$3:$C$100), "Yes", "No") -> No
B32: 30 | C32: =IFERROR(__xludf.DUMMYFUNCTION("""COMPUTED_VALUE"""),48761.0) -> 48761 | D32: =IF(C32 = MAX($C$3:$C$100), "Yes", "No") -> No
B33: 31 | C33: =IFERROR(__xludf.DUMMYFUNCTION("""COMPUTED_VALUE"""),48853.0) -> 48853 | D33: =IF(C33 = MAX($C$3:$C$100), "Yes", "No") -> No
B34: 32 | C34: =IFERROR(__xludf.DUMMYFUNCTION("""COMPUTED_VALUE"""),48945.0) -> 48945 | D34: =IF(C34 = MAX($C$3:$C$100), "Yes", "No") -> No
B35: 33 | C35: =IFERROR(__xludf.DUMMYFUNCTION("""COMPUTED_VALUE"""),49035.0) -> 49035 | D35: =IF(C35 = MAX($C$3:$C$100), "Yes", "No") -> No
B36: 34 | C36: =IFERROR(__xludf.DUMMYFUNCTION("""COMPUTED_VALUE"""),49126.0) -> 49126 | D36: =IF(C36 = MAX($C$3:$C$100), "Yes", "No") -> No
B37: 35 | C37: =IFERROR(__xludf.DUMMYFUNCTION("""COMPUTED_VALUE"""),49218.0) -> 49218 | D37: =IF(C37 = MAX($C$3:$C$100), "Yes", "No") -> No
B38: 36 | C38: =IFERROR(__xludf.DUMMYFUNCTION("""COMPUTED_VALUE"""),49310.0) -> 49310 | D38: =IF(C38 = MAX($C$3:$C$100), "Yes", "No") -> No
B39: 37 | C39: =IFERROR(__xludf.DUMMYFUNCTION("""COMPUTED_VALUE"""),49400.0) -> 49400 | D39: =IF(C39 = MAX($C$3:$C$100), "Yes", "No") -> No
B40: 38 | C40: =IFERROR(__xludf.DUMMYFUNCTION("""COMPUTED_VALUE"""),49491.0) -> 49491 | D40: =IF(C40 = MAX($C$3:$C$100), "Yes", "No") -> No
B41: 39 | C41: =IFERROR(__xludf.DUMMYFUNCTION("""COMPUTED_VALUE"""),49583.0) -> 49583 | D41: =IF(C41 = MAX($C$3:$C$100), "Yes", "No") -> No
...

Sheet Cashflows
B2: Coupon No | C2: Accrual Start | D2: Accrual End | E2: Days | F2: Year Fraction | G2: Coupon | H2: Principal
B3: ='Final Schedule'!B3 -> 1 | C3: =Inputs!C3 -> 46097 | D3: =IF('Final Schedule'!C3="","",'Final Schedule'!C3) -> 46113 | E3: =D3-C3 -> 16 | F3: =E3/365 -> 0.043835616 | G3: =Inputs!$J$2*Inputs!$E$3*F3 -> 31780.822 | H3: =IF(D3=Inputs!$D$3,Inputs!$J$2,0) -> 0
B4: ='Final Schedule'!B4 -> 2 | C4: =IF(D4 = "","",D3) -> 46113 | D4: =IF('Final Schedule'!C4="","",'Final Schedule'!C4) -> 46204 | E4: =D4-C4 -> 91 | F4: =E4/365 -> 0.24931507 | G4: =Inputs!$J$2*Inputs!$E$3*F4 -> 180753.42 | H4: =IF(D4=Inputs!$D$3,Inputs!$J$2,0) -> 0
B5: ='Final Schedule'!B5 -> 3 | C5: =IF(D5 = "","",D4) -> 46204 | D5: =IF('Final Schedule'!C5="","",'Final Schedule'!C5) -> 46296 | E5: =D5-C5 -> 92 | F5: =E5/365 -> 0.25205479 | G5: =Inputs!$J$2*Inputs!$E$3*F5 -> 182739.73 | H5: =IF(D5=Inputs!$D$3,Inputs!$J$2,0) -> 0
B6: ='Final Schedule'!B6 -> 4 | C6: =IF(D6 = "","",D5) -> 46296 | D6: =IF('Final Schedule'!C6="","",'Final Schedule'!C6) -> 46388 | E6: =D6-C6 -> 92 | F6: =E6/365 -> 0.25205479 | G6: =Inputs!$J$2*Inputs!$E$3*F6 -> 182739.73 | H6: =IF(D6=Inputs!$D$3,Inputs!$J$2,0) -> 0
B7: ='Final Schedule'!B7 -> 5 | C7: =IF(D7 = "","",D6) -> 46388 | D7: =IF('Final Schedule'!C7="","",'Final Schedule'!C7) -> 46478 | E7: =D7-C7 -> 90 | F7: =E7/365 -> 0.24657534 | G7: =Inputs!$J$2*Inputs!$E$3*F7 -> 178767.12 | H7: =IF(D7=Inputs!$D$3,Inputs!$J$2,0) -> 0
B8: ='Final Schedule'!B8 -> 6 | C8: =IF(D8 = "","",D7) -> 46478 | D8: =IF('Final Schedule'!C8="","",'Final Schedule'!C8) -> 46569 | E8: =D8-C8 -> 91 | F8: =E8/365 -> 0.24931507 | G8: =Inputs!$J$2*Inputs!$E$3*F8 -> 180753.42 | H8: =IF(D8=Inputs!$D$3,Inputs!$J$2,0) -> 0
B9: ='Final Schedule'!B9 -> 7 | C9: =IF(D9 = "","",D8) -> 46569 | D9: =IF('Final Schedule'!C9="","",'Final Schedule'!C9) -> 46661 | E9: =D9-C9 -> 92 | F9: =E9/365 -> 0.25205479 | G9: =Inputs!$J$2*Inputs!$E$3*F9 -> 182739.73 | H9: =IF(D9=Inputs!$D$3,Inputs!$J$2,0) -> 0
B10: ='Final Schedule'!B10 -> 8 | C10: =IF(D10 = "","",D9) -> 46661 | D10: =IF('Final Schedule'!C10="","",'Final Schedule'!C10) -> 46753 | E10: =D10-C10 -> 92 | F10: =E10/365 -> 0.25205479 | G10: =Inputs!$J$2*Inputs!$E$3*F10 -> 182739.73 | H10: =IF(D10=Inputs!$D$3,Inputs!$J$2,0) -> 0
B11: ='Final Schedule'!B11 -> 9 | C11: =IF(D11 = "","",D10) -> 46753 | D11: =IF('Final Schedule'!C11="","",'Final Schedule'!C11) -> 46844 | E11: =D11-C11 -> 91 | F11: =E11/365 -> 0.24931507 | G11: =Inputs!$J$2*Inputs!$E$3*F11 -> 180753.42 | H11: =IF(D11=Inputs!$D$3,Inputs!$J$2,0) -> 0
B12: ='Final Schedule'!B12 -> 10 | C12: =IF(D12 = "","",D11) -> 46844 | D12: =IF('Final Schedule'!C12="","",'Final Schedule'!C12) -> 46935 | E12: =D12-C12 -> 91 | F12: =E12/365 -> 0.24931507 | G12: =Inputs!$J$2*Inputs!$E$3*F12 -> 180753.42 | H12: =IF(D12=Inputs!$D$3,Inputs!$J$2,0) -> 0
B13: ='Final Schedule'!B13 -> 11 | C13: =IF(D13 = "","",D12) -> 46935 | D13: =IF('Final Schedule'!C13="","",'Final Schedule'!C13) -> 47027 | E13: =D13-C13 -> 92 | F13: =E13/365 -> 0.25205479 | G13: =Inputs!$J$2*Inputs!$E$3*F13 -> 182739.73 | H13: =IF(D13=Inputs!$D$3,Inputs!$J$2,0) -> 0
B14: ='Final Schedule'!B14 -> 12 | C14: =IF(D14 = "","",D13) -> 47027 | D14: =IF('Final Schedule'!C14="","",'Final Schedule'!C14) -> 47119 | E14: =D14-C14 -> 92 | F14: =E14/365 -> 0.25205479 | G14: =Inputs!$J$2*Inputs!$E$3*F14 -> 182739.73 | H14: =IF(D14=Inputs!$D$3,Inputs!$J$2,0) -> 0
B15: ='Final Schedule'!B15 -> 13 | C15: =IF(D15 = "","",D14) -> 47119 | D15: =IF('Final Schedule'!C15="","",'Final Schedule'!C15) -> 47209 | E15: =D15-C15 -> 90 | F15: =E15/365 -> 0.24657534 | G15: =Inputs!$J$2*Inputs!$E$3*F15 -> 178767.12 | H15: =IF(D15=Inputs!$D$3,Inputs!$J$2,0) -> 0
... B99: ='Final Schedule'!B99 | C99: =IF(D99 = "","",D98) | D99: =IF('Final Schedule'!C99="","",'Final Schedule'!C99) | E99: =D99-C99 -> 0 | F99: =E99/365 -> 0 | G99: =Inputs!$J$2*Inputs!$E$3*F99 -> 0 | H99: =IF(D99=Inputs!$D$3,Inputs!$J$2,0) -> 0
B100: ='Final Schedule'!B100

Sheet Valuation
B2: Coupon No | C2: Payment Date | D2: Total CF | E2: Tau | F2: DF | G2: PV
B3: =Cashflows!B3 -> 1 | C3: =Cashflows!D3 -> 46113 | D3: =Cashflows!G3+Cashflows!H3 -> 31780.822 | E3: =Cashflows!F3 -> 0.043835616 | F3: =EXP(-Inputs!$E$3*E3) -> 0.99682696 | G3: =F3*D3 -> 31679.98
B4: =Cashflows!B4 -> 2 | C4: =Cashflows!D4 -> 46204 | D4: =Cashflows!G4+Cashflows!H4 -> 180753.42 | E4: =Cashflows!F4 -> 0.24931507 | F4: =EXP(-Inputs!$E$3*E4) -> 0.98208704 | G4: =F4*D4 -> 177515.6 | I4: Bond Price | J4: =SUM(G3:G99) -> 23212136
B5: =Cashflows!B5 -> 3 | C5: =Cashflows!D5 -> 46296 | D5: =Cashflows!G5+Cashflows!H5 -> 182739.73 | E5: =Cashflows!F5 -> 0.25205479 | F5: =EXP(-Inputs!$E$3*E5) -> 0.98189198 | G5: =F5*D5 -> 179430.67
B6: =Cashflows!B6 -> 4 | C6: =Cashflows!D6 -> 46388 | D6: =Cashflows!G6+Cashflows!H6 -> 182739.73 | E6: =Cashflows!F6 -> 0.25205479 | F6: =EXP(-Inputs!$E$3*E6) -> 0.98189198 | G6: =F6*D6 -> 179430.67
B7: =Cashflows!B7 -> 5 | C7: =Cashflows!D7 -> 46478 | D7: =Cashflows!G7+Cashflows!H7 -> 178767.12 | E7: =Cashflows!F7 -> 0.24657534 | F7: =EXP(-Inputs!$E$3*E7) -> 0.98228213 | G7: =F7*D7 -> 175599.75
B8: =Cashflows!B8 -> 6 | C8: =Cashflows!D8 -> 46569 | D8: =Cashflows!G8+Cashflows!H8 -> 180753.42 | E8: =Cashflows!F8 -> 0.24931507 | F8: =EXP(-Inputs!$E$3*E8) -> 0.98208704 | G8: =F8*D8 -> 177515.6
B9: =Cashflows!B9 -> 7 | C9: =Cashflows!D9 -> 46661 | D9: =Cashflows!G9+Cashflows!H9 -> 182739.73 | E9: =Cashflows!F9 -> 0.25205479 | F9: =EXP(-Inputs!$E$3*E9) -> 0.98189198 | G9: =F9*D9 -> 179430.67
B10: =Cashflows!B10 -> 8 | C10: =Cashflows!D10 -> 46753 | D10: =Cashflows!G10+Cashflows!H10 -> 182739.73 | E10: =Cashflows!F10 -> 0.25205479 | F10: =EXP(-Inputs!$E$3*E10) -> 0.98189198 | G10: =F10*D10 -> 179430.67
B11: =Cashflows!B11 -> 9 | C11: =Cashflows!D11 -> 46844 | D11: =Cashflows!G11+Cashflows!H11 -> 180753.42 | E11: =Cashflows!F11 -> 0.24931507 | F11: =EXP(-Inputs!$E$3*E11) -> 0.98208704 | G11: =F11*D11 -> 177515.6
B12: =Cashflows!B12 -> 10 | C12: =Cashflows!D12 -> 46935 | D12: =Cashflows!G12+Cashflows!H12 -> 180753.42 | E12: =Cashflows!F12 -> 0.24931507 | F12: =EXP(-Inputs!$E$3*E12) -> 0.98208704 | G12: =F12*D12 -> 177515.6
B13: =Cashflows!B13 -> 11 | C13: =Cashflows!D13 -> 47027 | D13: =Cashflows!G13+Cashflows!H13 -> 182739.73 | E13: =Cashflows!F13 -> 0.25205479 | F13: =EXP(-Inputs!$E$3*E13) -> 0.98189198 | G13: =F13*D13 -> 179430.67
B14: =Cashflows!B14 -> 12 | C14: =Cashflows!D14 -> 47119 | D14: =Cashflows!G14+Cashflows!H14 -> 182739.73 | E14: =Cashflows!F14 -> 0.25205479 | F14: =EXP(-Inputs!$E$3*E14) -> 0.98189198 | G14: =F14*D14 -> 179430.67
B15: =Cashflows!B15 -> 13 | C15: =Cashflows!D15 -> 47209 | D15: =Cashflows!G15+Cashflows!H15 -> 178767.12 | E15: =Cashflows!F15 -> 0.24657534 | F15: =EXP(-Inputs!$E$3*E15) -> 0.98228213 | G15: =F15*D15 -> 175599.75
B16: =Cashflows!B16 -> 14 | C16: =Cashflows!D16 -> 47300 | D16: =Cashflows!G16+Cashflows!H16 -> 180753.42 | E16: =Cashflows!F16 -> 0.24931507 | F16: =EXP(-Inputs!$E$3*E16) -> 0.98208704 | G16: =F16*D16 -> 177515.6
... B99: =Cashflows!B99 | C99: =Cashflows!D99 | D99: =Cashflows!G99+Cashflows!H99 -> 0 | E99: =Cashflows!F99 -> 0 | F99: =EXP(-Inputs!$E$3*E99) -> 1 | G99: =F99*D99 -> 0
