Workbook

Sheet Inputs
A1: Inputs
A2: Notional (USD) | C2: 1000000
A3: Coupon Rate | C3: 0.05
A4: Coupon Frequency | C4: 1
A5: Maturity (Years) | C5: 2
A6: Spot FX (USD/INR) | C6: 90
A7: USD Zero Rate | C7: 0.035
A8: INR Zero Rate | C8: 0.068

Sheet Cashflow Schedule
A1: Payment | B1: Time (Years) | C1: Coupon | D1: Principal | E1: Total CF
A2: {=SEQUENCE(Inputs!C4*Inputs!C5,1,1,1)} -> 1 | B2: =IF(A2="","",A2/Inputs!$C$4) -> 1 | C2: =IF(A2="","",(Inputs!$C$3*Inputs!$C$2)/Inputs!$C$4) -> 50000 | D2: =IF(A2 = MAX($A$2:A1000), Inputs!$C$2, "") | E2: =IF(A2="","",D2+C2) -> 50000
A3: 2 | B3: =IF(A3="","",A3/Inputs!$C$4) -> 2 | C3: =IF(A3="","",(Inputs!$C$3*Inputs!$C$2)/Inputs!$C$4) -> 50000 | D3: =IF(A3 = MAX($A$2:A1000), Inputs!$C$2, "") -> 1000000 | E3: =IF(A3="","",D3+C3) -> 1050000
B4: =IF(A4="","",A4/Inputs!$C$4) | C4: =IF(A4="","",(Inputs!$C$3*Inputs!$C$2)/Inputs!$C$4) | D4: =IF(A4 = MAX($A$2:A1000), Inputs!$C$2, "") | E4: =IF(A4="","",D4+C4)
B5: =IF(A5="","",A5/Inputs!$C$4) | C5: =IF(A5="","",(Inputs!$C$3*Inputs!$C$2)/Inputs!$C$4) | D5: =IF(A5 = MAX($A$2:A1000), Inputs!$C$2, "") | E5: =IF(A5="","",D5+C5)
B6: =IF(A6="","",A6/Inputs!$C$4) | C6: =IF(A6="","",(Inputs!$C$3*Inputs!$C$2)/Inputs!$C$4) | D6: =IF(A6 = MAX($A$2:A1000), Inputs!$C$2, "") | E6: =IF(A6="","",D6+C6)
B7: =IF(A7="","",A7/Inputs!$C$4) | C7: =IF(A7="","",(Inputs!$C$3*Inputs!$C$2)/Inputs!$C$4) | D7: =IF(A7 = MAX($A$2:A1000), Inputs!$C$2, "") | E7: =IF(A7="","",D7+C7)
B8: =IF(A8="","",A8/Inputs!$C$4) | C8: =IF(A8="","",(Inputs!$C$3*Inputs!$C$2)/Inputs!$C$4) | D8: =IF(A8 = MAX($A$2:A1000), Inputs!$C$2, "") | E8: =IF(A8="","",D8+C8)
B9: =IF(A9="","",A9/Inputs!$C$4) | C9: =IF(A9="","",(Inputs!$C$3*Inputs!$C$2)/Inputs!$C$4) | D9: =IF(A9 = MAX($A$2:A1000), Inputs!$C$2, "") | E9: =IF(A9="","",D9+C9)
B10: =IF(A10="","",A10/Inputs!$C$4) | C10: =IF(A10="","",(Inputs!$C$3*Inputs!$C$2)/Inputs!$C$4) | D10: =IF(A10 = MAX($A$2:A1000), Inputs!$C$2, "") | E10: =IF(A10="","",D10+C10)
B11: =IF(A11="","",A11/Inputs!$C$4) | C11: =IF(A11="","",(Inputs!$C$3*Inputs!$C$2)/Inputs!$C$4) | D11: =IF(A11 = MAX($A$2:A1000), Inputs!$C$2, "") | E11: =IF(A11="","",D11+C11)
B12: =IF(A12="","",A12/Inputs!$C$4) | C12: =IF(A12="","",(Inputs!$C$3*Inputs!$C$2)/Inputs!$C$4) | D12: =IF(A12 = MAX($A$2:A1000), Inputs!$C$2, "") | E12: =IF(A12="","",D12+C12)
B13: =IF(A13="","",A13/Inputs!$C$4) | C13: =IF(A13="","",(Inputs!$C$3*Inputs!$C$2)/Inputs!$C$4) | D13: =IF(A13 = MAX($A$2:A1000), Inputs!$C$2, "") | E13: =IF(A13="","",D13+C13)
B14: =IF(A14="","",A14/Inputs!$C$4) | C14: =IF(A14="","",(Inputs!$C$3*Inputs!$C$2)/Inputs!$C$4) | D14: =IF(A14 = MAX($A$2:A1000), Inputs!$C$2, "") | E14: =IF(A14="","",D14+C14)
B15: =IF(A15="","",A15/Inputs!$C$4) | C15: =IF(A15="","",(Inputs!$C$3*Inputs!$C$2)/Inputs!$C$4) | D15: =IF(A15 = MAX($A$2:A1000), Inputs!$C$2, "") | E15: =IF(A15="","",D15+C15)
B16: =IF(A16="","",A16/Inputs!$C$4) | C16: =IF(A16="","",(Inputs!$C$3*Inputs!$C$2)/Inputs!$C$4) | D16: =IF(A16 = MAX($A$2:A1000), Inputs!$C$2, "") | E16: =IF(A16="","",D16+C16)
B17: =IF(A17="","",A17/Inputs!$C$4) | C17: =IF(A17="","",(Inputs!$C$3*Inputs!$C$2)/Inputs!$C$4) | D17: =IF(A17 = MAX($A$2:A1000), Inputs!$C$2, "") | E17: =IF(A17="","",D17+C17)
B18: =IF(A18="","",A18/Inputs!$C$4) | C18: =IF(A18="","",(Inputs!$C$3*Inputs!$C$2)/Inputs!$C$4) | D18: =IF(A18 = MAX($A$2:A1000), Inputs!$C$2, "") | E18: =IF(A18="","",D18+C18)
B19: =IF(A19="","",A19/Inputs!$C$4) | C19: =IF(A19="","",(Inputs!$C$3*Inputs!$C$2)/Inputs!$C$4) | D19: =IF(A19 = MAX($A$2:A1000), Inputs!$C$2, "") | E19: =IF(A19="","",D19+C19)
B20: =IF(A20="","",A20/Inputs!$C$4) | C20: =IF(A20="","",(Inputs!$C$3*Inputs!$C$2)/Inputs!$C$4) | D20: =IF(A20 = MAX($A$2:A1000), Inputs!$C$2, "") | E20: =IF(A20="","",D20+C20)
B21: =IF(A21="","",A21/Inputs!$C$4) | C21: =IF(A21="","",(Inputs!$C$3*Inputs!$C$2)/Inputs!$C$4) | D21: =IF(A21 = MAX($A$2:A1000), Inputs!$C$2, "") | E21: =IF(A21="","",D21+C21)
B22: =IF(A22="","",A22/Inputs!$C$4) | C22: =IF(A22="","",(Inputs!$C$3*Inputs!$C$2)/Inputs!$C$4) | D22: =IF(A22 = MAX($A$2:A1000), Inputs!$C$2, "") | E22: =IF(A22="","",D22+C22)
B23: =IF(A23="","",A23/Inputs!$C$4) | C23: =IF(A23="","",(Inputs!$C$3*Inputs!$C$2)/Inputs!$C$4) | D23: =IF(A23 = MAX($A$2:A1000), Inputs!$C$2, "") | E23: =IF(A23="","",D23+C23)
B24: =IF(A24="","",A24/Inputs!$C$4) | C24: =IF(A24="","",(Inputs!$C$3*Inputs!$C$2)/Inputs!$C$4) | D24: =IF(A24 = MAX($A$2:A1000), Inputs!$C$2, "") | E24: =IF(A24="","",D24+C24)
B25: =IF(A25="","",A25/Inputs!$C$4) | C25: =IF(A25="","",(Inputs!$C$3*Inputs!$C$2)/Inputs!$C$4) | D25: =IF(A25 = MAX($A$2:A1000), Inputs!$C$2, "") | E25: =IF(A25="","",D25+C25)
B26: =IF(A26="","",A26/Inputs!$C$4) | C26: =IF(A26="","",(Inputs!$C$3*Inputs!$C$2)/Inputs!$C$4) | D26: =IF(A26 = MAX($A$2:A1000), Inputs!$C$2, "") | E26: =IF(A26="","",D26+C26)
B27: =IF(A27="","",A27/Inputs!$C$4) | C27: =IF(A27="","",(Inputs!$C$3*Inputs!$C$2)/Inputs!$C$4) | D27: =IF(A27 = MAX($A$2:A1000), Inputs!$C$2, "") | E27: =IF(A27="","",D27+C27)
B28: =IF(A28="","",A28/Inputs!$C$4) | C28: =IF(A28="","",(Inputs!$C$3*Inputs!$C$2)/Inputs!$C$4) | D28: =IF(A28 = MAX($A$2:A1000), Inputs!$C$2, "") | E28: =IF(A28="","",D28+C28)
B29: =IF(A29="","",A29/Inputs!$C$4) | C29: =IF(A29="","",(Inputs!$C$3*Inputs!$C$2)/Inputs!$C$4) | D29: =IF(A29 = MAX($A$2:A1000), Inputs!$C$2, "") | E29: =IF(A29="","",D29+C29)
B30: =IF(A30="","",A30/Inputs!$C$4) | C30: =IF(A30="","",(Inputs!$C$3*Inputs!$C$2)/Inputs!$C$4) | D30: =IF(A30 = MAX($A$2:A1000), Inputs!$C$2, "") | E30: =IF(A30="","",D30+C30)
B31: =IF(A31="","",A31/Inputs!$C$4) | C31: =IF(A31="","",(Inputs!$C$3*Inputs!$C$2)/Inputs!$C$4) | D31: =IF(A31 = MAX($A$2:A1000), Inputs!$C$2, "") | E31: =IF(A31="","",D31+C31)
B32: =IF(A32="","",A32/Inputs!$C$4) | C32: =IF(A32="","",(Inputs!$C$3*Inputs!$C$2)/Inputs!$C$4) | D32: =IF(A32 = MAX($A$2:A1000), Inputs!$C$2, "") | E32: =IF(A32="","",D32+C32)
B33: =IF(A33="","",A33/Inputs!$C$4) | C33: =IF(A33="","",(Inputs!$C$3*Inputs!$C$2)/Inputs!$C$4) | D33: =IF(A33 = MAX($A$2:A1000), Inputs!$C$2, "") | E33: =IF(A33="","",D33+C33)
B34: =IF(A34="","",A34/Inputs!$C$4) | C34: =IF(A34="","",(Inputs!$C$3*Inputs!$C$2)/Inputs!$C$4) | D34: =IF(A34 = MAX($A$2:A1000), Inputs!$C$2, "") | E34: =IF(A34="","",D34+C34)
B35: =IF(A35="","",A35/Inputs!$C$4) | C35: =IF(A35="","",(Inputs!$C$3*Inputs!$C$2)/Inputs!$C$4) | D35: =IF(A35 = MAX($A$2:A1000), Inputs!$C$2, "") | E35: =IF(A35="","",D35+C35)
B36: =IF(A36="","",A36/Inputs!$C$4) | C36: =IF(A36="","",(Inputs!$C$3*Inputs!$C$2)/Inputs!$C$4) | D36: =IF(A36 = MAX($A$2:A1000), Inputs!$C$2, "") | E36: =IF(A36="","",D36+C36)
B37: =IF(A37="","",A37/Inputs!$C$4) | C37: =IF(A37="","",(Inputs!$C$3*Inputs!$C$2)/Inputs!$C$4) | D37: =IF(A37 = MAX($A$2:A1000), Inputs!$C$2, "") | E37: =IF(A37="","",D37+C37)
B38: =IF(A38="","",A38/Inputs!$C$4) | C38: =IF(A38="","",(Inputs!$C$3*Inputs!$C$2)/Inputs!$C$4) | D38: =IF(A38 = MAX($A$2:A1000), Inputs!$C$2, "") | E38: =IF(A38="","",D38+C38)
B39: =IF(A39="","",A39/Inputs!$C$4) | C39: =IF(A39="","",(Inputs!$C$3*Inputs!$C$2)/Inputs!$C$4) | D39: =IF(A39 = MAX($A$2:A1000), Inputs!$C$2, "") | E39: =IF(A39="","",D39+C39)
B40: =IF(A40="","",A40/Inputs!$C$4) | C40: =IF(A40="","",(Inputs!$C$3*Inputs!$C$2)/Inputs!$C$4) | D40: =IF(A40 = MAX($A$2:A1000), Inputs!$C$2, "") | E40: =IF(A40="","",D40+C40)
...

Sheet Path A
A1: Year | B1: USD CF | C1: USD DF | D1: USD PV | E1: INR PV
A2: ='Cashflow Schedule'!B2 -> 1 | B2: ='Cashflow Schedule'!E2 -> 50000 | C2: =IF(A2="","",EXP(-Inputs!$C$7*A2)) -> 0.96560542 | D2: =IF(A2="","",B2*C2) -> 48280.271 | E2: =IF(A2="","",Inputs!$C$6*D2) -> 4345224.4
A3: ='Cashflow Schedule'!B3 -> 2 | B3: ='Cashflow Schedule'!E3 -> 1050000 | C3: =IF(A3="","",EXP(-Inputs!$C$7*A3)) -> 0.93239382 | D3: =IF(A3="","",B3*C3) -> 979013.51 | E3: =IF(A3="","",Inputs!$C$6*D3) -> 88111216
A4: ='Cashflow Schedule'!B4 | B4: ='Cashflow Schedule'!E4 | C4: =IF(A4="","",EXP(-Inputs!$C$7*A4)) | D4: =IF(A4="","",B4*C4) | E4: =IF(A4="","",Inputs!$C$6*D4) | H4: Total Present Value | J4: =SUM(E2:E1000) -> 92456440
A5: ='Cashflow Schedule'!B5 | B5: ='Cashflow Schedule'!E5 | C5: =IF(A5="","",EXP(-Inputs!$C$7*A5)) | D5: =IF(A5="","",B5*C5) | E5: =IF(A5="","",Inputs!$C$6*D5)
A6: ='Cashflow Schedule'!B6 | B6: ='Cashflow Schedule'!E6 | C6: =IF(A6="","",EXP(-Inputs!$C$7*A6)) | D6: =IF(A6="","",B6*C6) | E6: =IF(A6="","",Inputs!$C$6*D6)
A7: ='Cashflow Schedule'!B7 | B7: ='Cashflow Schedule'!E7 | C7: =IF(A7="","",EXP(-Inputs!$C$7*A7)) | D7: =IF(A7="","",B7*C7) | E7: =IF(A7="","",Inputs!$C$6*D7)
A8: ='Cashflow Schedule'!B8 | B8: ='Cashflow Schedule'!E8 | C8: =IF(A8="","",EXP(-Inputs!$C$7*A8)) | D8: =IF(A8="","",B8*C8) | E8: =IF(A8="","",Inputs!$C$6*D8)
A9: ='Cashflow Schedule'!B9 | B9: ='Cashflow Schedule'!E9 | C9: =IF(A9="","",EXP(-Inputs!$C$7*A9)) | D9: =IF(A9="","",B9*C9) | E9: =IF(A9="","",Inputs!$C$6*D9)
A10: ='Cashflow Schedule'!B10 | B10: ='Cashflow Schedule'!E10 | C10: =IF(A10="","",EXP(-Inputs!$C$7*A10)) | D10: =IF(A10="","",B10*C10) | E10: =IF(A10="","",Inputs!$C$6*D10)
A11: ='Cashflow Schedule'!B11 | B11: ='Cashflow Schedule'!E11 | C11: =IF(A11="","",EXP(-Inputs!$C$7*A11)) | D11: =IF(A11="","",B11*C11) | E11: =IF(A11="","",Inputs!$C$6*D11)
A12: ='Cashflow Schedule'!B12 | B12: ='Cashflow Schedule'!E12 | C12: =IF(A12="","",EXP(-Inputs!$C$7*A12)) | D12: =IF(A12="","",B12*C12) | E12: =IF(A12="","",Inputs!$C$6*D12)
A13: ='Cashflow Schedule'!B13 | B13: ='Cashflow Schedule'!E13 | C13: =IF(A13="","",EXP(-Inputs!$C$7*A13)) | D13: =IF(A13="","",B13*C13) | E13: =IF(A13="","",Inputs!$C$6*D13)
A14: ='Cashflow Schedule'!B14 | B14: ='Cashflow Schedule'!E14 | C14: =IF(A14="","",EXP(-Inputs!$C$7*A14)) | D14: =IF(A14="","",B14*C14) | E14: =IF(A14="","",Inputs!$C$6*D14)
A15: ='Cashflow Schedule'!B15 | B15: ='Cashflow Schedule'!E15 | C15: =IF(A15="","",EXP(-Inputs!$C$7*A15)) | D15: =IF(A15="","",B15*C15) | E15: =IF(A15="","",Inputs!$C$6*D15)
A16: ='Cashflow Schedule'!B16 | B16: ='Cashflow Schedule'!E16 | C16: =IF(A16="","",EXP(-Inputs!$C$7*A16)) | D16: =IF(A16="","",B16*C16) | E16: =IF(A16="","",Inputs!$C$6*D16)
... A1000: ='Cashflow Schedule'!B1000 | B1000: ='Cashflow Schedule'!E1000 | C1000: =IF(A1000="","",EXP(-Inputs!$C$7*A1000)) | D1000: =IF(A1000="","",B1000*C1000) | E1000: =IF(A1000="","",Inputs!$C$6*D1000)

Sheet Path B
A1: Year | B1: USD CF | C1: Forward FX | D1: INR CF | E1: INR DF | F1: INR PV
A2: ='Cashflow Schedule'!B2 -> 1 | B2: ='Cashflow Schedule'!E2 -> 50000 | C2: =IF(A2="","",Inputs!$C$6*EXP((Inputs!$C$8-Inputs!$C$7)*A2)) -> 93.019549 | D2: =IF(A2="","",B2*C2) -> 4650977.4 | E2: =IF(A2="","",EXP(-Inputs!$C$8*A2)) -> 0.93426047 | F2: =IF(A2="","",E2*D2) -> 4345224.4
A3: ='Cashflow Schedule'!B3 -> 2 | B3: ='Cashflow Schedule'!E3 -> 1050000 | C3: =IF(A3="","",Inputs!$C$6*EXP((Inputs!$C$8-Inputs!$C$7)*A3)) -> 96.140405 | D3: =IF(A3="","",B3*C3) -> 1.0094742e+08 | E3: =IF(A3="","",EXP(-Inputs!$C$8*A3)) -> 0.87284263 | F3: =IF(A3="","",E3*D3) -> 88111216
A4: ='Cashflow Schedule'!B4 | B4: ='Cashflow Schedule'!E4 | C4: =IF(A4="","",Inputs!$C$6*EXP((Inputs!$C$8-Inputs!$C$7)*A4)) | D4: =IF(A4="","",B4*C4) | E4: =IF(A4="","",EXP(-Inputs!$C$8*A4)) | F4: =IF(A4="","",E4*D4)
A5: ='Cashflow Schedule'!B5 | B5: ='Cashflow Schedule'!E5 | C5: =IF(A5="","",Inputs!$C$6*EXP((Inputs!$C$8-Inputs!$C$7)*A5)) | D5: =IF(A5="","",B5*C5) | E5: =IF(A5="","",EXP(-Inputs!$C$8*A5)) | F5: =IF(A5="","",E5*D5) | H5: Total Present Value | J5: =SUM(F2:F1000) -> 92456440
A6: ='Cashflow Schedule'!B6 | B6: ='Cashflow Schedule'!E6 | C6: =IF(A6="","",Inputs!$C$6*EXP((Inputs!$C$8-Inputs!$C$7)*A6)) | D6: =IF(A6="","",B6*C6) | E6: =IF(A6="","",EXP(-Inputs!$C$8*A6)) | F6: =IF(A6="","",E6*D6)
A7: ='Cashflow Schedule'!B7 | B7: ='Cashflow Schedule'!E7 | C7: =IF(A7="","",Inputs!$C$6*EXP((Inputs!$C$8-Inputs!$C$7)*A7)) | D7: =IF(A7="","",B7*C7) | E7: =IF(A7="","",EXP(-Inputs!$C$8*A7)) | F7: =IF(A7="","",E7*D7)
A8: ='Cashflow Schedule'!B8 | B8: ='Cashflow Schedule'!E8 | C8: =IF(A8="","",Inputs!$C$6*EXP((Inputs!$C$8-Inputs!$C$7)*A8)) | D8: =IF(A8="","",B8*C8) | E8: =IF(A8="","",EXP(-Inputs!$C$8*A8)) | F8: =IF(A8="","",E8*D8)
A9: ='Cashflow Schedule'!B9 | B9: ='Cashflow Schedule'!E9 | C9: =IF(A9="","",Inputs!$C$6*EXP((Inputs!$C$8-Inputs!$C$7)*A9)) | D9: =IF(A9="","",B9*C9) | E9: =IF(A9="","",EXP(-Inputs!$C$8*A9)) | F9: =IF(A9="","",E9*D9)
A10: ='Cashflow Schedule'!B10 | B10: ='Cashflow Schedule'!E10 | C10: =IF(A10="","",Inputs!$C$6*EXP((Inputs!$C$8-Inputs!$C$7)*A10)) | D10: =IF(A10="","",B10*C10) | E10: =IF(A10="","",EXP(-Inputs!$C$8*A10)) | F10: =IF(A10="","",E10*D10)
A11: ='Cashflow Schedule'!B11 | B11: ='Cashflow Schedule'!E11 | C11: =IF(A11="","",Inputs!$C$6*EXP((Inputs!$C$8-Inputs!$C$7)*A11)) | D11: =IF(A11="","",B11*C11) | E11: =IF(A11="","",EXP(-Inputs!$C$8*A11)) | F11: =IF(A11="","",E11*D11)
A12: ='Cashflow Schedule'!B12 | B12: ='Cashflow Schedule'!E12 | C12: =IF(A12="","",Inputs!$C$6*EXP((Inputs!$C$8-Inputs!$C$7)*A12)) | D12: =IF(A12="","",B12*C12) | E12: =IF(A12="","",EXP(-Inputs!$C$8*A12)) | F12: =IF(A12="","",E12*D12)
A13: ='Cashflow Schedule'!B13 | B13: ='Cashflow Schedule'!E13 | C13: =IF(A13="","",Inputs!$C$6*EXP((Inputs!$C$8-Inputs!$C$7)*A13)) | D13: =IF(A13="","",B13*C13) | E13: =IF(A13="","",EXP(-Inputs!$C$8*A13)) | F13: =IF(A13="","",E13*D13)
A14: ='Cashflow Schedule'!B14 | B14: ='Cashflow Schedule'!E14 | C14: =IF(A14="","",Inputs!$C$6*EXP((Inputs!$C$8-Inputs!$C$7)*A14)) | D14: =IF(A14="","",B14*C14) | E14: =IF(A14="","",EXP(-Inputs!$C$8*A14)) | F14: =IF(A14="","",E14*D14)
A15: ='Cashflow Schedule'!B15 | B15: ='Cashflow Schedule'!E15 | C15: =IF(A15="","",Inputs!$C$6*EXP((Inputs!$C$8-Inputs!$C$7)*A15)) | D15: =IF(A15="","",B15*C15) | E15: =IF(A15="","",EXP(-Inputs!$C$8*A15)) | F15: =IF(A15="","",E15*D15)
A16: ='Cashflow Schedule'!B16 | B16: ='Cashflow Schedule'!E16 | C16: =IF(A16="","",Inputs!$C$6*EXP((Inputs!$C$8-Inputs!$C$7)*A16)) | D16: =IF(A16="","",B16*C16) | E16: =IF(A16="","",EXP(-Inputs!$C$8*A16)) | F16: =IF(A16="","",E16*D16)
A17: ='Cashflow Schedule'!B17 | B17: ='Cashflow Schedule'!E17 | C17: =IF(A17="","",Inputs!$C$6*EXP((Inputs!$C$8-Inputs!$C$7)*A17)) | D17: =IF(A17="","",B17*C17) | E17: =IF(A17="","",EXP(-Inputs!$C$8*A17)) | F17: =IF(A17="","",E17*D17)
... A1000: ='Cashflow Schedule'!B1000 | B1000: ='Cashflow Schedule'!E1000 | C1000: =IF(A1000="","",Inputs!$C$6*EXP((Inputs!$C$8-Inputs!$C$7)*A1000)) | D1000: =IF(A1000="","",B1000*C1000) | E1000: =IF(A1000="","",EXP(-Inputs!$C$8*A1000)) | F1000: =IF(A1000="","",E1000*D1000)
